[2025-05-28 23:57:08,265] {taskinstance.py:1159} INFO - Dependencies all met for <TaskInstance: WordCountDAG.generate_word_count scheduled__2025-05-27T00:00:00+00:00 [queued]>
[2025-05-28 23:57:08,274] {taskinstance.py:1159} INFO - Dependencies all met for <TaskInstance: WordCountDAG.generate_word_count scheduled__2025-05-27T00:00:00+00:00 [queued]>
[2025-05-28 23:57:08,274] {taskinstance.py:1356} INFO - 
--------------------------------------------------------------------------------
[2025-05-28 23:57:08,274] {taskinstance.py:1357} INFO - Starting attempt 1 of 1
[2025-05-28 23:57:08,274] {taskinstance.py:1358} INFO - 
--------------------------------------------------------------------------------
[2025-05-28 23:57:08,300] {taskinstance.py:1377} INFO - Executing <Task(WordCountOperator): generate_word_count> on 2025-05-27 00:00:00+00:00
[2025-05-28 23:57:08,306] {standard_task_runner.py:52} INFO - Started process 18200 to run task
[2025-05-28 23:57:08,315] {standard_task_runner.py:79} INFO - Running: ['airflow', 'tasks', 'run', 'WordCountDAG', 'generate_word_count', 'scheduled__2025-05-27T00:00:00+00:00', '--job-id', '9', '--raw', '--subdir', 'DAGS_FOLDER/twitter_dag.py', '--cfg-path', '/tmp/tmp8f1b12_8', '--error-file', '/tmp/tmpr13fkewv']
[2025-05-28 23:57:08,328] {standard_task_runner.py:80} INFO - Job 9: Subtask generate_word_count
[2025-05-28 23:57:08,406] {task_command.py:370} INFO - Running <TaskInstance: WordCountDAG.generate_word_count scheduled__2025-05-27T00:00:00+00:00 [running]> on host alura
[2025-05-28 23:57:08,468] {taskinstance.py:1569} INFO - Exporting the following env vars:
AIRFLOW_CTX_DAG_OWNER=airflow
AIRFLOW_CTX_DAG_ID=WordCountDAG
AIRFLOW_CTX_TASK_ID=generate_word_count
AIRFLOW_CTX_EXECUTION_DATE=2025-05-27T00:00:00+00:00
AIRFLOW_CTX_TRY_NUMBER=1
AIRFLOW_CTX_DAG_RUN_ID=scheduled__2025-05-27T00:00:00+00:00
[2025-05-28 23:57:08,470] {taskinstance.py:1889} ERROR - Task failed with exception
Traceback (most recent call last):
  File "/home/cunhaaw/Downloads/APITwitter/airflow_pipeline/operators/twitter_operator.py", line 81, in execute
    with open(self.input_path, "r") as f:
FileNotFoundError: [Errno 2] No such file or directory: 'datalake/processed_tweets/extract_date=2025-05-27/cleaned_tweets.json'
[2025-05-28 23:57:08,474] {taskinstance.py:1395} INFO - Marking task as FAILED. dag_id=WordCountDAG, task_id=generate_word_count, execution_date=20250527T000000, start_date=20250529T025708, end_date=20250529T025708
[2025-05-28 23:57:08,488] {standard_task_runner.py:92} ERROR - Failed to execute job 9 for task generate_word_count ([Errno 2] No such file or directory: 'datalake/processed_tweets/extract_date=2025-05-27/cleaned_tweets.json'; 18200)
[2025-05-28 23:57:08,532] {local_task_job.py:156} INFO - Task exited with return code 1
[2025-05-28 23:57:08,608] {local_task_job.py:273} INFO - 0 downstream tasks scheduled from follow-on schedule check
